#VRML_SIM R2019a utf8
WorldInfo {
}
Viewpoint {
  orientation 0.9973979856131489 -0.06927648274704207 -0.0199506198658503 5.721001738173353
  position 0.7859094703196391 2.177381952083303 3.1283288160297156
}
TexturedBackground {
}
TexturedBackgroundLight {
}
Floor {
}
Solid {
  translation 0 0.5 0
  children [
    Shape {
      appearance PBRAppearance {
        baseColor 0 0 0
      }
      geometry DEF G_CLY Cylinder {
        height 1
        radius 0.15
      }
    }
    HingeJoint {
      jointParameters HingeJointParameters {
        axis 0 1 0
        anchor 0 0.5 0
        staticFriction 0.05
      }
      endPoint Solid {
        translation 0.25 0.525 0
        children [
          Shape {
            appearance PBRAppearance {
              baseColor 0.6431372549019608 0 0
            }
            geometry DEF G_RBOX Box {
              size 0.5 0.05 0.1
            }
          }
          HingeJoint {
            jointParameters HingeJointParameters {
              axis 0 0 1
              anchor 0.25 0 0
              staticFriction 0.01
            }
            endPoint Solid {
              translation 0.3 0 0
              rotation 0 0 1 0
              children [
                Shape {
                  appearance PBRAppearance {
                    baseColor 0.3058823529411765 0.6039215686274509 0.023529411764705882
                  }
                  geometry DEF G_GBOX Box {
                    size 0.1 0.05 0.1
                  }
                }
                HingeJoint {
                  jointParameters HingeJointParameters {
                    anchor 0.05 0 0
                    staticFriction 0.01
                  }
                  endPoint Solid {
                    translation 0.125 0 0
                    children [
                      Shape {
                        appearance PBRAppearance {
                          baseColor 0.12549019607843137 0.2901960784313726 0.5294117647058824
                        }
                        geometry DEF G_BBOX Box {
                          size 0.15 0.05 0.1
                        }
                      }
                    ]
                    boundingObject USE G_BBOX
                    physics Physics {
                    }
                  }
                }
              ]
              boundingObject USE G_GBOX
              physics Physics {
              }
            }
          }
        ]
        boundingObject USE G_RBOX
        physics Physics {
        }
      }
    }
  ]
  boundingObject USE G_CLY
}
